Workbook

Sheet Original Data
A1: Sector | B1: Year | C1: Month | D1: Cereals and products | E1: Meat and fish | F1: Egg | G1: Milk and products | H1: Oils and fats | I1: Fruits | J1: Vegetables | K1: Pulses and products | L1: Sugar and Confectionery | M1: Spices | N1: Non-alcoholic beverages | O1: Prepared meals, snacks, sweets etc. | P1: Food and beverages | Q1: Pan, tobacco and intoxicants | R1: Clothing | S1: Footwear | T1: Clothing and footwear | U1: Housing | V1: Fuel and light | W1: Household goods and services | X1: Health | Y1: Transport and communication | Z1: Recreation and amusement | AA1: Education | AB1: Personal care and effects | AC1: Miscellaneous | AD1: General index
A2: Rural | B2: 2013 | C2: January | D2: 107.5 | E2: 106.3 | F2: 108.1 | G2: 104.9 | H2: 106.1 | I2: 103.9 | J2: 101.9 | K2: 106.1 | L2: 106.8 | M2: 103.1 | N2: 104.8 | O2: 106.7 | P2: 105.5 | Q2: 105.1 | R2: 106.5 | S2: 105.8 | T2: 106.4 | U2: NA | V2: 105.5 | W2: 104.8 | X2: 104 | Y2: 103.3 | Z2: 103.4 | AA2: 103.8 | AB2: 104.7 | AC2: 104 | AD2: 105.1
A3: Urban | B3: 2013 | C3: January | D3: 110.5 | E3: 109.1 | F3: 113 | G3: 103.6 | H3: 103.4 | I3: 102.3 | J3: 102.9 | K3: 105.8 | L3: 105.1 | M3: 101.8 | N3: 105.1 | O3: 107.9 | P3: 105.9 | Q3: 105.2 | R3: 105.9 | S3: 105 | T3: 105.8 | U3: 100.3 | V3: 105.4 | W3: 104.8 | X3: 104.1 | Y3: 103.2 | Z3: 102.9 | AA3: 103.5 | AB3: 104.3 | AC3: 103.7 | AD3: 104
A4: Rural+Urban | B4: 2013 | C4: January | D4: 108.4 | E4: 107.3 | F4: 110 | G4: 104.4 | H4: 105.1 | I4: 103.2 | J4: 102.2 | K4: 106 | L4: 106.2 | M4: 102.7 | N4: 104.9 | O4: 107.3 | P4: 105.6 | Q4: 105.1 | R4: 106.3 | S4: 105.5 | T4: 106.2 | U4: 100.3 | V4: 105.5 | W4: 104.8 | X4: 104 | Y4: 103.2 | Z4: 103.1 | AA4: 103.6 | AB4: 104.5 | AC4: 103.9 | AD4: 104.6
A5: Rural | B5: 2013 | C5: February | D5: 109.2 | E5: 108.7 | F5: 110.2 | G5: 105.4 | H5: 106.7 | I5: 104 | J5: 102.4 | K5: 105.9 | L5: 105.7 | M5: 103.1 | N5: 105.1 | O5: 107.7 | P5: 106.3 | Q5: 105.6 | R5: 107.1 | S5: 106.3 | T5: 107 | U5: NA | V5: 106.2 | W5: 105.2 | X5: 104.4 | Y5: 103.9 | Z5: 104 | AA5: 104.1 | AB5: 104.6 | AC5: 104.4 | AD5: 105.8
A6: Urban | B6: 2013 | C6: February | D6: 112.9 | E6: 112.9 | F6: 116.9 | G6: 104 | H6: 103.5 | I6: 103.1 | J6: 104.9 | K6: 104.1 | L6: 103.8 | M6: 102.3 | N6: 106 | O6: 109 | P6: 107.2 | Q6: 106 | R6: 106.6 | S6: 105.5 | T6: 106.4 | U6: 100.4 | V6: 105.7 | W6: 105.2 | X6: 104.7 | Y6: 104.4 | Z6: 103.3 | AA6: 103.7 | AB6: 104.3 | AC6: 104.3 | AD6: 104.7
A7: Rural+Urban | B7: 2013 | C7: February | D7: 110.4 | E7: 110.2 | F7: 112.8 | G7: 104.9 | H7: 105.5 | I7: 103.6 | J7: 103.2 | K7: 105.3 | L7: 105.1 | M7: 102.8 | N7: 105.5 | O7: 108.3 | P7: 106.6 | Q7: 105.7 | R7: 106.9 | S7: 106 | T7: 106.8 | U7: 100.4 | V7: 106 | W7: 105.2 | X7: 104.5 | Y7: 104.2 | Z7: 103.6 | AA7: 103.9 | AB7: 104.5 | AC7: 104.4 | AD7: 105.3
A8: Rural | B8: 2013 | C8: March | D8: 110.2 | E8: 108.8 | F8: 109.9 | G8: 105.6 | H8: 106.2 | I8: 105.7 | J8: 101.4 | K8: 105.7 | L8: 105 | M8: 103.3 | N8: 105.6 | O8: 108.2 | P8: 106.6 | Q8: 106.5 | R8: 107.6 | S8: 106.8 | T8: 107.5 | U8: NA | V8: 106.1 | W8: 105.6 | X8: 104.7 | Y8: 104.6 | Z8: 104 | AA8: 104.3 | AB8: 104.3 | AC8: 104.6 | AD8: 106
A9: Urban | B9: 2013 | C9: March | D9: 113.9 | E9: 111.4 | F9: 113.2 | G9: 104.3 | H9: 102.7 | I9: 104.9 | J9: 103.8 | K9: 103.5 | L9: 102.6 | M9: 102.4 | N9: 107 | O9: 109.8 | P9: 107.3 | Q9: 106.8 | R9: 107.2 | S9: 106 | T9: 107 | U9: 100.4 | V9: 106 | W9: 105.7 | X9: 105.2 | Y9: 105.5 | Z9: 103.5 | AA9: 103.8 | AB9: 104.2 | AC9: 104.9 | AD9: 105
A10: Rural+Urban | B10: 2013 | C10: March | D10: 111.4 | E10: 109.7 | F10: 111.2 | G10: 105.1 | H10: 104.9 | I10: 105.3 | J10: 102.2 | K10: 105 | L10: 104.2 | M10: 103 | N10: 106.2 | O10: 108.9 | P10: 106.9 | Q10: 106.6 | R10: 107.4 | S10: 106.5 | T10: 107.3 | U10: 100.4 | V10: 106.1 | W10: 105.6 | X10: 104.9 | Y10: 105.1 | Z10: 103.7 | AA10: 104 | AB10: 104.3 | AC10: 104.7 | AD10: 105.5
A11: Rural | B11: 2013 | C11: April | D11: 110.2 | E11: 109.5 | F11: 106.9 | G11: 106.3 | H11: 105.7 | I11: 108.3 | J11: 103.4 | K11: 105.7 | L11: 104.2 | M11: 103.2 | N11: 106.5 | O11: 108.8 | P11: 107.1 | Q11: 107.1 | R11: 108.1 | S11: 107.4 | T11: 108 | U11: NA | V11: 106.5 | W11: 106.1 | X11: 105.1 | Y11: 104.4 | Z11: 104.5 | AA11: 104.8 | AB11: 102.7 | AC11: 104.6 | AD11: 106.4
A12: Urban | B12: 2013 | C12: April | D12: 114.6 | E12: 113.4 | F12: 106 | G12: 104.7 | H12: 102.1 | I12: 109.5 | J12: 109.7 | K12: 104.6 | L12: 102 | M12: 103.5 | N12: 108.2 | O12: 110.6 | P12: 108.8 | Q12: 108.5 | R12: 107.9 | S12: 106.4 | T12: 107.7 | U12: 100.5 | V12: 106.4 | W12: 106.5 | X12: 105.7 | Y12: 105 | Z12: 104 | AA12: 105.2 | AB12: 103.2 | AC12: 105.1 | AD12: 105.7
A13: Rural+Urban | B13: 2013 | C13: April | D13: 111.6 | E13: 110.9 | F13: 106.6 | G13: 105.7 | H13: 104.4 | I13: 108.9 | J13: 105.5 | K13: 105.3 | L13: 103.5 | M13: 103.3 | N13: 107.2 | O13: 109.6 | P13: 107.7 | Q13: 107.5 | R13: 108 | S13: 107 | T13: 107.9 | U13: 100.5 | V13: 106.5 | W13: 106.3 | X13: 105.3 | Y13: 104.7 | Z13: 104.2 | AA13: 105 | AB13: 102.9 | AC13: 104.8 | AD13: 106.1
A14: Rural | B14: 2013 | C14: May | D14: 110.9 | E14: 109.8 | F14: 105.9 | G14: 107.5 | H14: 105.3 | I14: 108.1 | J14: 107.3 | K14: 106.1 | L14: 103.7 | M14: 104 | N14: 107.4 | O14: 109.9 | P14: 108.1 | Q14: 108.1 | R14: 108.8 | S14: 107.9 | T14: 108.6 | U14: NA | V14: 107.5 | W14: 106.8 | X14: 105.7 | Y14: 104.1 | Z14: 105 | AA14: 105.5 | AB14: 102.1 | AC14: 104.8 | AD14: 107.2
A15: Urban | B15: 2013 | C15: May | D15: 115.4 | E15: 114.2 | F15: 102.7 | G15: 105.5 | H15: 101.5 | I15: 110.6 | J15: 123.7 | K15: 105.2 | L15: 101.9 | M15: 105 | N15: 109.1 | O15: 111.3 | P15: 111.1 | Q15: 109.8 | R15: 108.5 | S15: 106.7 | T15: 108.3 | U15: 100.5 | V15: 107.2 | W15: 107.1 | X15: 106.2 | Y15: 103.9 | Z15: 104.6 | AA15: 105.7 | AB15: 102.6 | AC15: 104.9 | AD15: 106.6
A16: Rural+Urban | B16: 2013 | C16: May | D16: 112.3 | E16: 111.3 | F16: 104.7 | G16: 106.8 | H16: 103.9 | I16: 109.3 | J16: 112.9 | K16: 105.8 | L16: 103.1 | M16: 104.3 | N16: 108.1 | O16: 110.5 | P16: 109.2 | Q16: 108.6 | R16: 108.7 | S16: 107.4 | T16: 108.5 | U16: 100.5 | V16: 107.4 | W16: 106.9 | X16: 105.9 | Y16: 104 | Z16: 104.8 | AA16: 105.6 | AB16: 102.3 | AC16: 104.8 | AD16: 106.9
A17: Rural | B17: 2013 | C17: June | D17: 112.3 | E17: 112.1 | F17: 108.1 | G17: 108.3 | H17: 105.9 | I17: 109.2 | J17: 118 | K17: 106.8 | L17: 104.1 | M17: 105.4 | N17: 108.2 | O17: 111 | P17: 110.6 | Q17: 109 | R17: 109.7 | S17: 108.8 | T17: 109.5 | U17: NA | V17: 108.5 | W17: 107.5 | X17: 106.3 | Y17: 105 | Z17: 105.6 | AA17: 106.5 | AB17: 102.5 | AC17: 105.5 | AD17: 108.9
A18: Urban | B18: 2013 | C18: June | D18: 117 | E18: 120.1 | F18: 112.5 | G18: 107.3 | H18: 101.3 | I18: 112.4 | J18: 143.6 | K18: 105.4 | L18: 101.4 | M18: 106.4 | N18: 110 | O18: 112.2 | P18: 115 | Q18: 110.9 | R18: 109.2 | S18: 107.2 | T18: 108.9 | U18: 106.6 | V18: 108 | W18: 107.7 | X18: 106.5 | Y18: 105.2 | Z18: 105.2 | AA18: 108.1 | AB18: 103.3 | AC18: 106.1 | AD18: 109.7
A19: Rural+Urban | B19: 2013 | C19: June | D19: 113.8 | E19: 114.9 | F19: 109.8 | G19: 107.9 | H19: 104.2 | I19: 110.7 | J19: 126.7 | K19: 106.3 | L19: 103.2 | M19: 105.7 | N19: 109 | O19: 111.6 | P19: 112.2 | Q19: 109.5 | R19: 109.5 | S19: 108.1 | T19: 109.3 | U19: 106.6 | V19: 108.3 | W19: 107.6 | X19: 106.4 | Y19: 105.1 | Z19: 105.4 | AA19: 107.4 | AB19: 102.8 | AC19: 105.8 | AD19: 109.3
A20: Rural | B20: 2013 | C20: July | D20: 113.4 | E20: 114.9 | F20: 110.5 | G20: 109.3 | H20: 106.2 | I20: 110.3 | J20: 129.2 | K20: 107.1 | L20: 104.3 | M20: 106.4 | N20: 109.1 | O20: 112.1 | P20: 113.1 | Q20: 109.8 | R20: 110.5 | S20: 109.5 | T20: 110.3 | U20: NA | V20: 109.5 | W20: 108.3 | X20: 106.9 | Y20: 106.8 | Z20: 106.4 | AA20: 107.8 | AB20: 102.5 | AC20: 106.5 | AD20: 110.7
A21: Urban | B21: 2013 | C21: July | D21: 117.8 | E21: 119.2 | F21: 114 | G21: 108.3 | H21: 101.1 | I21: 113.2 | J21: 160.9 | K21: 105.1 | L21: 101.3 | M21: 107.5 | N21: 110.4 | O21: 113.1 | P21: 117.5 | Q21: 111.7 | R21: 109.8 | S21: 107.8 | T21: 109.5 | U21: 107.7 | V21: 108.6 | W21: 108.1 | X21: 107.1 | Y21: 107.3 | Z21: 105.9 | AA21: 110.1 | AB21: 103.2 | AC21: 107.3 | AD21: 111.4
A22: Rural+Urban | B22: 2013 | C22: July | D22: 114.8 | E22: 116.4 | F22: 111.9 | G22: 108.9 | H22: 104.3 | I22: 111.7 | J22: 140 | K22: 106.4 | L22: 103.3 | M22: 106.8 | N22: 109.6 | O22: 112.6 | P22: 114.7 | Q22: 110.3 | R22: 110.2 | S22: 108.8 | T22: 110 | U22: 107.7 | V22: 109.2 | W22: 108.2 | X22: 107 | Y22: 107.1 | Z22: 106.1 | AA22: 109.1 | AB22: 102.8 | AC22: 106.9 | AD22: 111
A23: Rural | B23: 2013 | C23: August | D23: 114.3 | E23: 115.4 | F23: 111.1 | G23: 110 | H23: 106.4 | I23: 110.8 | J23: 138.9 | K23: 107.4 | L23: 104.1 | M23: 106.9 | N23: 109.7 | O23: 112.6 | P23: 114.9 | Q23: 110.7 | R23: 111.3 | S23: 110.2 | T23: 111.1 | U23: NA | V23: 109.9 | W23: 108.7 | X23: 107.5 | Y23: 107.8 | Z23: 106.8 | AA23: 108.7 | AB23: 105 | AC23: 107.5 | AD23: 112.1
A24: Urban | B24: 2013 | C24: August | D24: 118.3 | E24: 120.4 | F24: 112.7 | G24: 108.9 | H24: 101.1 | I24: 108.7 | J24: 177 | K24: 104.7 | L24: 101 | M24: 108.5 | N24: 110.9 | O24: 114.3 | P24: 119.6 | Q24: 112.4 | R24: 110.6 | S24: 108.3 | T24: 110.2 | U24: 108.9 | V24: 109.3 | W24: 108.7 | X24: 107.6 | Y24: 108.1 | Z24: 106.5 | AA24: 110.8 | AB24: 106 | AC24: 108.3 | AD24: 112.7
A25: Rural+Urban | B25: 2013 | C25: August | D25: 115.6 | E25: 117.2 | F25: 111.7 | G25: 109.6 | H25: 104.5 | I25: 109.8 | J25: 151.8 | K25: 106.5 | L25: 103.1 | M25: 107.4 | N25: 110.2 | O25: 113.4 | P25: 116.6 | Q25: 111.2 | R25: 111 | S25: 109.4 | T25: 110.7 | U25: 108.9 | V25: 109.7 | W25: 108.7 | X25: 107.5 | Y25: 108 | Z25: 106.6 | AA25: 109.9 | AB25: 105.4 | AC25: 107.9 | AD25: 112.4
A26: Rural | B26: 2013 | C26: September | D26: 115.4 | E26: 115.7 | F26: 111.7 | G26: 111 | H26: 107.4 | I26: 110.9 | J26: 154 | K26: 108.1 | L26: 104.2 | M26: 107.9 | N26: 110.4 | O26: 114 | P26: 117.8 | Q26: 111.7 | R26: 112.7 | S26: 111.4 | T26: 112.5 | U26: NA | V26: 111.1 | W26: 109.6 | X26: 108.3 | Y26: 109.3 | Z26: 107.7 | AA26: 109.8 | AB26: 106.7 | AC26: 108.7 | AD26: 114.2
A27: Urban | B27: 2013 | C27: September | D27: 118.6 | E27: 119.1 | F27: 113.2 | G27: 109.6 | H27: 101.7 | I27: 103.2 | J27: 174.3 | K27: 105.1 | L27: 100.8 | M27: 109.1 | N27: 111.1 | O27: 115.4 | P27: 119.2 | Q27: 112.9 | R27: 111.4 | S27: 109 | T27: 111.1 | U27: 109.7 | V27: 109.5 | W27: 109.6 | X27: 107.9 | Y27: 110.4 | Z27: 107.4 | AA27: 111.2 | AB27: 106.9 | AC27: 109.4 | AD27: 113.2
A28: Rural+Urban | B28: 2013 | C28: September | D28: 116.4 | E28: 116.9 | F28: 112.3 | G28: 110.5 | H28: 105.3 | I28: 107.3 | J28: 160.9 | K28: 107.1 | L28: 103.1 | M28: 108.3 | N28: 110.7 | O28: 114.6 | P28: 118.3 | Q28: 112 | R28: 112.2 | S28: 110.4 | T28: 111.9 | U28: 109.7 | V28: 110.5 | W28: 109.6 | X28: 108.1 | Y28: 109.9 | Z28: 107.5 | AA28: 110.6 | AB28: 106.8 | AC28: 109 | AD28: 113.7
A29: Rural | B29: 2013 | C29: October | D29: 116.3 | E29: 115.4 | F29: 112.6 | G29: 111.7 | H29: 107.7 | I29: 113.2 | J29: 164.9 | K29: 108.3 | L29: 103.9 | M29: 108.2 | N29: 111.1 | O29: 114.9 | P29: 119.8 | Q29: 112.2 | R29: 113.6 | S29: 112.3 | T29: 113.4 | U29: NA | V29: 111.6 | W29: 110.4 | X29: 108.9 | Y29: 109.3 | Z29: 108.3 | AA29: 110.2 | AB29: 107.5 | AC29: 109.1 | AD29: 115.5
A30: Urban | B30: 2013 | C30: October | D30: 118.9 | E30: 118.1 | F30: 114.5 | G30: 110.4 | H30: 102.3 | I30: 106.2 | J30: 183.5 | K30: 105.3 | L30: 100.2 | M30: 109.6 | N30: 111.4 | O30: 116 | P30: 120.8 | Q30: 113.5 | R30: 112.5 | S30: 109.7 | T30: 112 | U30: 110.5 | V30: 109.7 | W30: 110.2 | X30: 108.2 | Y30: 109.7 | Z30: 108 | AA30: 111.3 | AB30: 107.3 | AC30: 109.4 | AD30: 114
A31: Rural+Urban | B31: 2013 | C31: October | D31: 117.1 | E31: 116.3 | F31: 113.3 | G31: 111.2 | H31: 105.7 | I31: 109.9 | J31: 171.2 | K31: 107.3 | L31: 102.7 | M31: 108.7 | N31: 111.2 | O31: 115.4 | P31: 120.2 | Q31: 112.5 | R31: 113.2 | S31: 111.2 | T31: 112.8 | U31: 110.5 | V31: 110.9 | W31: 110.3 | X31: 108.6 | Y31: 109.5 | Z31: 108.1 | AA31: 110.8 | AB31: 107.4 | AC31: 109.2 | AD31: 114.8
A32: Rural | B32: 2013 | C32: November | D32: 117.3 | E32: 114.9 | F32: 116.2 | G32: 112.8 | H32: 108.9 | I32: 116.6 | J32: 178.1 | K32: 109.1 | L32: 103.6 | M32: 109 | N32: 111.8 | O32: 116 | P32: 122.5 | Q32: 112.8 | R32: 114.6 | S32: 113.1 | T32: 114.4 | U32: NA | V32: 112.6 | W32: 111.3 | X32: 109.7 | Y32: 109.6 | Z32: 108.7 | AA32: 111 | AB32: 108.2 | AC32: 109.8 | AD32: 117.4
A33: Urban | B33: 2013 | C33: November | D33: 119.8 | E33: 116.3 | F33: 122.6 | G33: 112 | H33: 103.2 | I33: 110 | J33: 192.8 | K33: 106.3 | L33: 99.5 | M33: 110.3 | N33: 111.8 | O33: 117.1 | P33: 122.9 | Q33: 114.1 | R33: 113.5 | S33: 110.3 | T33: 113 | U33: 111.1 | V33: 110 | W33: 110.9 | X33: 108.6 | Y33: 109.5 | Z33: 108.5 | AA33: 111.3 | AB33: 107.9 | AC33: 109.6 | AD33: 115
A34: Rural+Urban | B34: 2013 | C34: November | D34: 118.1 | E34: 115.4 | F34: 118.7 | G34: 112.5 | H34: 106.8 | I34: 113.5 | J34: 183.1 | K34: 108.2 | L34: 102.2 | M34: 109.4 | N34: 111.8 | O34: 116.5 | P34: 122.6 | Q34: 113.1 | R34: 114.2 | S34: 111.9 | T34: 113.8 | U34: 111.1 | V34: 111.6 | W34: 111.1 | X34: 109.3 | Y34: 109.5 | Z34: 108.6 | AA34: 111.2 | AB34: 108.1 | AC34: 109.7 | AD34: 116.3
A35: Rural | B35: 2013 | C35: December | D35: 118.4 | E35: 115.9 | F35: 120.4 | G35: 113.8 | H35: 109.5 | I35: 115.5 | J35: 145.7 | K35: 109.5 | L35: 102.9 | M35: 109.8 | N35: 112.1 | O35: 116.8 | P35: 118.7 | Q35: 113.6 | R35: 115.8 | S35: 114 | T35: 115.5 | U35: NA | V35: 112.8 | W35: 112.1 | X35: 110.1 | Y35: 109.9 | Z35: 109.2 | AA35: 111.6 | AB35: 108.1 | AC35: 110.1 | AD35: 115.5
A36: Urban | B36: 2013 | C36: December | D36: 120.5 | E36: 118.1 | F36: 128.5 | G36: 112.8 | H36: 103.4 | I36: 110.7 | J36: 144.8 | K36: 107.1 | L36: 98.6 | M36: 111.9 | N36: 112.1 | O36: 118.1 | P36: 117.8 | Q36: 115 | R36: 114.2 | S36: 110.9 | T36: 113.7 | U36: 110.7 | V36: 110.4 | W36: 111.3 | X36: 109 | Y36: 109.7 | Z36: 108.9 | AA36: 111.4 | AB36: 107.7 | AC36: 109.8 | AD36: 113.3
A37: Rural+Urban | B37: 2013 | C37: December | D37: 119.1 | E37: 116.7 | F37: 123.5 | G37: 113.4 | H37: 107.3 | I37: 113.3 | J37: 145.4 | K37: 108.7 | L37: 101.5 | M37: 110.5 | N37: 112.1 | O37: 117.4 | P37: 118.4 | Q37: 114 | R37: 115.2 | S37: 112.7 | T37: 114.8 | U37: 110.7 | V37: 111.9 | W37: 111.7 | X37: 109.7 | Y37: 109.8 | Z37: 109 | AA37: 111.5 | AB37: 107.9 | AC37: 110 | AD37: 114.5
A38: Rural | B38: 2014 | C38: January | D38: 118.9 | E38: 117.1 | F38: 120.5 | G38: 114.4 | H38: 109 | I38: 115.5 | J38: 123.9 | K38: 109.6 | L38: 101.8 | M38: 110.2 | N38: 112.4 | O38: 117.3 | P38: 116 | Q38: 114 | R38: 116.5 | S38: 114.5 | T38: 116.2 | U38: NA | V38: 113 | W38: 112.6 | X38: 110.6 | Y38: 110.5 | Z38: 109.6 | AA38: 111.8 | AB38: 108.3 | AC38: 110.6 | AD38: 114.2
A39: Urban | B39: 2014 | C39: January | D39: 121.2 | E39: 122 | F39: 129.9 | G39: 113.6 | H39: 102.9 | I39: 112.1 | J39: 118.9 | K39: 107.5 | L39: 96.9 | M39: 112.7 | N39: 112.1 | O39: 119 | P39: 115.5 | Q39: 115.7 | R39: 114.8 | S39: 111.3 | T39: 114.3 | U39: 111.6 | V39: 111 | W39: 111.9 | X39: 109.7 | Y39: 110.8 | Z39: 109.8 | AA39: 111.5 | AB39: 108 | AC39: 110.5 | AD39: 112.9
A40: Rural+Urban | B40: 2014 | C40: January | D40: 119.6 | E40: 118.8 | F40: 124.1 | G40: 114.1 | H40: 106.8 | I40: 113.9 | J40: 122.2 | K40: 108.9 | L40: 100.2 | M40: 111 | N40: 112.3 | O40: 118.1 | P40: 115.8 | Q40: 114.5 | R40: 115.8 | S40: 113.2 | T40: 115.4 | U40: 111.6 | V40: 112.2 | W40: 112.3 | X40: 110.3 | Y40: 110.7 | Z40: 109.7 | AA40: 111.6 | AB40: 108.2 | AC40: 110.6 | AD40: 113.6
...

Sheet Sheet4
A1: Month Year | B1: 45047
A3: Row Labels | B3: Average of CPI Value | C3: Average of CPI Value2
A4: Recreation and amusement | B4: 1.0413643 | C4: 186.55
A5: Health | B5: 1.0340144 | C5: 185.23333
A6: Clothing and footwear | B6: 1.0245246 | C6: 183.53333
A7: Fuel and light | B7: 1.0209892 | C7: 182.9
A8: Household Items | B8: 1.005545 | C8: 180.13333
A9: General index | B9: 0.99940456 | C9: 179.03333
A10: Food &Beverage | B10: 0.99230512 | C10: 177.76154
A11: Education | B11: 0.99028693 | C11: 177.4
A12: Miscellaneous | B12: 0.98023892 | C12: 175.6
A13: Housing | B13: 0.98023892 | C13: 175.6
A14: Transport and communication | B14: 0.92088125 | C14: 164.96667
A15: Grand Total | B15: 1 | C15: 179.14

Sheet Sheet2
A1: Sector | B1: Year | C1: Month | D1: Month Year | E1: Categories | F1: CPI Value | G1: New Clubbed Category
A2: Rural | B2: 2013 | C2: January | D2: 41275 | E2: Cereals and products | F2: 107.5 | G2: =VLOOKUP(Table1_2[[#This Row],[Categories]],Sheet3!$A$1:$B$27,2,FALSE) -> Food &Beverage
A3: Rural | B3: 2013 | C3: January | D3: 41275 | E3: Meat and fish | F3: 106.3 | G3: =VLOOKUP(Table1_2[[#This Row],[Categories]],Sheet3!$A$1:$B$27,2,FALSE) -> Food &Beverage
A4: Rural | B4: 2013 | C4: January | D4: 41275 | E4: Egg | F4: 108.1 | G4: =VLOOKUP(Table1_2[[#This Row],[Categories]],Sheet3!$A$1:$B$27,2,FALSE) -> Food &Beverage
A5: Rural | B5: 2013 | C5: January | D5: 41275 | E5: Milk and products | F5: 104.9 | G5: =VLOOKUP(Table1_2[[#This Row],[Categories]],Sheet3!$A$1:$B$27,2,FALSE) -> Food &Beverage
A6: Rural | B6: 2013 | C6: January | D6: 41275 | E6: Oils and fats | F6: 106.1 | G6: =VLOOKUP(Table1_2[[#This Row],[Categories]],Sheet3!$A$1:$B$27,2,FALSE) -> Food &Beverage
A7: Rural | B7: 2013 | C7: January | D7: 41275 | E7: Fruits | F7: 103.9 | G7: =VLOOKUP(Table1_2[[#This Row],[Categories]],Sheet3!$A$1:$B$27,2,FALSE) -> Food &Beverage
A8: Rural | B8: 2013 | C8: January | D8: 41275 | E8: Vegetables | F8: 101.9 | G8: =VLOOKUP(Table1_2[[#This Row],[Categories]],Sheet3!$A$1:$B$27,2,FALSE) -> Food &Beverage
A9: Rural | B9: 2013 | C9: January | D9: 41275 | E9: Pulses and products | F9: 106.1 | G9: =VLOOKUP(Table1_2[[#This Row],[Categories]],Sheet3!$A$1:$B$27,2,FALSE) -> Food &Beverage
A10: Rural | B10: 2013 | C10: January | D10: 41275 | E10: Sugar and Confectionery | F10: 106.8 | G10: =VLOOKUP(Table1_2[[#This Row],[Categories]],Sheet3!$A$1:$B$27,2,FALSE) -> Food &Beverage
A11: Rural | B11: 2013 | C11: January | D11: 41275 | E11: Spices | F11: 103.1 | G11: =VLOOKUP(Table1_2[[#This Row],[Categories]],Sheet3!$A$1:$B$27,2,FALSE) -> Food &Beverage
A12: Rural | B12: 2013 | C12: January | D12: 41275 | E12: Non-alcoholic beverages | F12: 104.8 | G12: =VLOOKUP(Table1_2[[#This Row],[Categories]],Sheet3!$A$1:$B$27,2,FALSE) -> Food &Beverage
A13: Rural | B13: 2013 | C13: January | D13: 41275 | E13: Prepared meals, snacks, sweets etc. | F13: 106.7 | G13: =VLOOKUP(Table1_2[[#This Row],[Categories]],Sheet3!$A$1:$B$27,2,FALSE) -> Food &Beverage
... A801: Rural+Urban | B801: 2013 | C801: October | D801: 41548 | E801: General index | F801: 114.8 | G801: =VLOOKUP(Table1_2[[#This Row],[Categories]],Sheet3!$A$1:$B$27,2,FALSE) -> General index
G802: =VLOOKUP(Table1_2[[#This Row],[Categories]],Sheet3!$A$1:$B$27,2,FALSE) -> #N/A
G803: =VLOOKUP(Table1_2[[#This Row],[Categories]],Sheet3!$A$1:$B$27,2,FALSE) -> #N/A
G804: =VLOOKUP(Table1_2[[#This Row],[Categories]],Sheet3!$A$1:$B$27,2,FALSE) -> #N/A
G805: =VLOOKUP(Table1_2[[#This Row],[Categories]],Sheet3!$A$1:$B$27,2,FALSE) -> #N/A
G806: =VLOOKUP(Table1_2[[#This Row],[Categories]],Sheet3!$A$1:$B$27,2,FALSE) -> #N/A
G807: =VLOOKUP(Table1_2[[#This Row],[Categories]],Sheet3!$A$1:$B$27,2,FALSE) -> #N/A
G808: =VLOOKUP(Table1_2[[#This Row],[Categories]],Sheet3!$A$1:$B$27,2,FALSE) -> #N/A
G809: =VLOOKUP(Table1_2[[#This Row],[Categories]],Sheet3!$A$1:$B$27,2,FALSE) -> #N/A
G810: =VLOOKUP(Table1_2[[#This Row],[Categories]],Sheet3!$A$1:$B$27,2,FALSE) -> #N/A
G811: =VLOOKUP(Table1_2[[#This Row],[Categories]],Sheet3!$A$1:$B$27,2,FALSE) -> #N/A
G812: =VLOOKUP(Table1_2[[#This Row],[Categories]],Sheet3!$A$1:$B$27,2,FALSE) -> #N/A
G813: =VLOOKUP(Table1_2[[#This Row],[Categories]],Sheet3!$A$1:$B$27,2,FALSE) -> #N/A
... G827: =VLOOKUP(Table1_2[[#This Row],[Categories]],Sheet3!$A$1:$B$27,2,FALSE) -> #N/A
A828: Urban | B828: 2013 | C828: November | D828: 41579 | E828: Cereals and products | F828: 119.8 | G828: =VLOOKUP(Table1_2[[#This Row],[Categories]],Sheet3!$A$1:$B$27,2,FALSE) -> Food &Beverage
A829: Urban | B829: 2013 | C829: November | D829: 41579 | E829: Meat and fish | F829: 116.3 | G829: =VLOOKUP(Table1_2[[#This Row],[Categories]],Sheet3!$A$1:$B$27,2,FALSE) -> Food &Beverage
A830: Urban | B830: 2013 | C830: November | D830: 41579 | E830: Egg | F830: 122.6 | G830: =VLOOKUP(Table1_2[[#This Row],[Categories]],Sheet3!$A$1:$B$27,2,FALSE) -> Food &Beverage
A831: Urban | B831: 2013 | C831: November | D831: 41579 | E831: Milk and products | F831: 112 | G831: =VLOOKUP(Table1_2[[#This Row],[Categories]],Sheet3!$A$1:$B$27,2,FALSE) -> Food &Beverage
A832: Urban | B832: 2013 | C832: November | D832: 41579 | E832: Oils and fats | F832: 103.2 | G832: =VLOOKUP(Table1_2[[#This Row],[Categories]],Sheet3!$A$1:$B$27,2,FALSE) -> Food &Beverage
A833: Urban | B833: 2013 | C833: November | D833: 41579 | E833: Fruits | F833: 110 | G833: =VLOOKUP(Table1_2[[#This Row],[Categories]],Sheet3!$A$1:$B$27,2,FALSE) -> Food &Beverage
A834: Urban | B834: 2013 | C834: November | D834: 41579 | E834: Vegetables | F834: 192.8 | G834: =VLOOKUP(Table1_2[[#This Row],[Categories]],Sheet3!$A$1:$B$27,2,FALSE) -> Food &Beverage
A835: Urban | B835: 2013 | C835: November | D835: 41579 | E835: Pulses and products | F835: 106.3 | G835: =VLOOKUP(Table1_2[[#This Row],[Categories]],Sheet3!$A$1:$B$27,2,FALSE) -> Food &Beverage
A836: Urban | B836: 2013 | C836: November | D836: 41579 | E836: Sugar and Confectionery | F836: 99.5 | G836: =VLOOKUP(Table1_2[[#This Row],[Categories]],Sheet3!$A$1:$B$27,2,FALSE) -> Food &Beverage
A837: Urban | B837: 2013 | C837: November | D837: 41579 | E837: Spices | F837: 110.3 | G837: =VLOOKUP(Table1_2[[#This Row],[Categories]],Sheet3!$A$1:$B$27,2,FALSE) -> Food &Beverage
A838: Urban | B838: 2013 | C838: November | D838: 41579 | E838: Non-alcoholic beverages | F838: 111.8 | G838: =VLOOKUP(Table1_2[[#This Row],[Categories]],Sheet3!$A$1:$B$27,2,FALSE) -> Food &Beverage
A839: Urban | B839: 2013 | C839: November | D839: 41579 | E839: Prepared meals, snacks, sweets etc. | F839: 117.1 | G839: =VLOOKUP(Table1_2[[#This Row],[Categories]],Sheet3!$A$1:$B$27,2,FALSE) -> Food &Beverage
... A9817: Rural+Urban | B9817: 2023 | C9817: May | D9817: 45047 | E9817: Transport and communication | F9817: 164.8 | G9817: =VLOOKUP(Table1_2[[#This Row],[Categories]],Sheet3!$A$1:$B$27,2,FALSE) -> Transport and communication

Sheet Sheet3
A1: Cereals and products | B1: Food &Beverage
A2: Meat and fish | B2: =B1 -> Food &Beverage
A3: Egg | B3: =B2 -> Food &Beverage
A4: Milk and products | B4: =B3 -> Food &Beverage
A5: Oils and fats | B5: =B4 -> Food &Beverage
A6: Fruits | B6: =B5 -> Food &Beverage
A7: Vegetables | B7: =B6 -> Food &Beverage
A8: Pulses and products | B8: =B7 -> Food &Beverage
A9: Sugar and Confectionery | B9: =B8 -> Food &Beverage
A10: Spices | B10: =B9 -> Food &Beverage
A11: Non-alcoholic beverages | B11: =B10 -> Food &Beverage
A12: Prepared meals, snacks, sweets etc. | B12: =B11 -> Food &Beverage
A13: Food and beverages | B13: =B12 -> Food &Beverage
A14: Clothing | B14: Clothing and footwear
A15: Footwear | B15: =B14 -> Clothing and footwear
A16: Clothing and footwear | B16: =B15 -> Clothing and footwear
A17: Fuel and light | B17: Fuel and light
A18: Health | B18: Health
A19: Transport and communication | B19: Transport and communication
A20: Recreation and amusement | B20: Recreation and amusement
A21: Pan, tobacco and intoxicants | B21: =B20 -> Recreation and amusement
A22: Miscellaneous | B22: Miscellaneous
A23: General index | B23: General index
A24: Housing | B24: Housing
A25: Education | B25: Education
A26: Personal care and effects | B26: Household Items
A27: Household goods and services | B27: =B26 -> Household Items

Sheet Working Data
A1: Sector | B1: Year | C1: Month | D1: Cereals and products | E1: Meat and fish | F1: Egg | G1: Milk and products | H1: Oils and fats | I1: Fruits | J1: Vegetables | K1: Pulses and products | L1: Sugar and Confectionery | M1: Spices | N1: Non-alcoholic beverages | O1: Prepared meals, snacks, sweets etc. | P1: Food and beverages | Q1: Pan, tobacco and intoxicants | R1: Clothing | S1: Footwear | T1: Clothing and footwear | U1: Housing | V1: Fuel and light | W1: Household goods and services | X1: Health | Y1: Transport and communication | Z1: Recreation and amusement | AA1: Education | AB1: Personal care and effects | AC1: Miscellaneous | AD1: General index | AE1: Month Year
A2: Rural | B2: 2013 | C2: January | D2: 107.5 | E2: 106.3 | F2: 108.1 | G2: 104.9 | H2: 106.1 | I2: 103.9 | J2: 101.9 | K2: 106.1 | L2: 106.8 | M2: 103.1 | N2: 104.8 | O2: 106.7 | P2: 105.5 | Q2: 105.1 | R2: 106.5 | S2: 105.8 | T2: 106.4 | U2: =U3 -> 100.3 | V2: 105.5 | W2: 104.8 | X2: 104 | Y2: 103.3 | Z2: 103.4 | AA2: 103.8 | AB2: 104.7 | AC2: 104 | AD2: 105.1 | AE2: =DATE(B2, MATCH(C2,{"January","February","March","April","May","June","July","August","September","October","November","December"}, 0),1) -> 41275
A3: Urban | B3: 2013 | C3: January | D3: 110.5 | E3: 109.1 | F3: 113 | G3: 103.6 | H3: 103.4 | I3: 102.3 | J3: 102.9 | K3: 105.8 | L3: 105.1 | M3: 101.8 | N3: 105.1 | O3: 107.9 | P3: 105.9 | Q3: 105.2 | R3: 105.9 | S3: 105 | T3: 105.8 | U3: 100.3 | V3: 105.4 | W3: 104.8 | X3: 104.1 | Y3: 103.2 | Z3: 102.9 | AA3: 103.5 | AB3: 104.3 | AC3: 103.7 | AD3: 104 | AE3: =DATE(B3, MATCH(C3,{"January","February","March","April","May","June","July","August","September","October","November","December"}, 0),1) -> 41275
A4: Rural+Urban | B4: 2013 | C4: January | D4: 108.4 | E4: 107.3 | F4: 110 | G4: 104.4 | H4: 105.1 | I4: 103.2 | J4: 102.2 | K4: 106 | L4: 106.2 | M4: 102.7 | N4: 104.9 | O4: 107.3 | P4: 105.6 | Q4: 105.1 | R4: 106.3 | S4: 105.5 | T4: 106.2 | U4: 100.3 | V4: 105.5 | W4: 104.8 | X4: 104 | Y4: 103.2 | Z4: 103.1 | AA4: 103.6 | AB4: 104.5 | AC4: 103.9 | AD4: 104.6 | AE4: =DATE(B4, MATCH(C4,{"January","February","March","April","May","June","July","August","September","October","November","December"}, 0),1) -> 41275
A5: Rural | B5: 2013 | C5: February | D5: 109.2 | E5: 108.7 | F5: 110.2 | G5: 105.4 | H5: 106.7 | I5: 104 | J5: 102.4 | K5: 105.9 | L5: 105.7 | M5: 103.1 | N5: 105.1 | O5: 107.7 | P5: 106.3 | Q5: 105.6 | R5: 107.1 | S5: 106.3 | T5: 107 | U5: =U6 -> 100.4 | V5: 106.2 | W5: 105.2 | X5: 104.4 | Y5: 103.9 | Z5: 104 | AA5: 104.1 | AB5: 104.6 | AC5: 104.4 | AD5: 105.8 | AE5: =DATE(B5, MATCH(C5,{"January","February","March","April","May","June","July","August","September","October","November","December"}, 0),1) -> 41306
A6: Urban | B6: 2013 | C6: February | D6: 112.9 | E6: 112.9 | F6: 116.9 | G6: 104 | H6: 103.5 | I6: 103.1 | J6: 104.9 | K6: 104.1 | L6: 103.8 | M6: 102.3 | N6: 106 | O6: 109 | P6: 107.2 | Q6: 106 | R6: 106.6 | S6: 105.5 | T6: 106.4 | U6: 100.4 | V6: 105.7 | W6: 105.2 | X6: 104.7 | Y6: 104.4 | Z6: 103.3 | AA6: 103.7 | AB6: 104.3 | AC6: 104.3 | AD6: 104.7 | AE6: =DATE(B6, MATCH(C6,{"January","February","March","April","May","June","July","August","September","October","November","December"}, 0),1) -> 41306
A7: Rural+Urban | B7: 2013 | C7: February | D7: 110.4 | E7: 110.2 | F7: 112.8 | G7: 104.9 | H7: 105.5 | I7: 103.6 | J7: 103.2 | K7: 105.3 | L7: 105.1 | M7: 102.8 | N7: 105.5 | O7: 108.3 | P7: 106.6 | Q7: 105.7 | R7: 106.9 | S7: 106 | T7: 106.8 | U7: 100.4 | V7: 106 | W7: 105.2 | X7: 104.5 | Y7: 104.2 | Z7: 103.6 | AA7: 103.9 | AB7: 104.5 | AC7: 104.4 | AD7: 105.3 | AE7: =DATE(B7, MATCH(C7,{"January","February","March","April","May","June","July","August","September","October","November","December"}, 0),1) -> 41306
A8: Rural | B8: 2013 | C8: March | D8: 110.2 | E8: 108.8 | F8: 109.9 | G8: 105.6 | H8: 106.2 | I8: 105.7 | J8: 101.4 | K8: 105.7 | L8: 105 | M8: 103.3 | N8: 105.6 | O8: 108.2 | P8: 106.6 | Q8: 106.5 | R8: 107.6 | S8: 106.8 | T8: 107.5 | U8: =U9 -> 100.4 | V8: 106.1 | W8: 105.6 | X8: 104.7 | Y8: 104.6 | Z8: 104 | AA8: 104.3 | AB8: 104.3 | AC8: 104.6 | AD8: 106 | AE8: =DATE(B8, MATCH(C8,{"January","February","March","April","May","June","July","August","September","October","November","December"}, 0),1) -> 41334
A9: Urban | B9: 2013 | C9: March | D9: 113.9 | E9: 111.4 | F9: 113.2 | G9: 104.3 | H9: 102.7 | I9: 104.9 | J9: 103.8 | K9: 103.5 | L9: 102.6 | M9: 102.4 | N9: 107 | O9: 109.8 | P9: 107.3 | Q9: 106.8 | R9: 107.2 | S9: 106 | T9: 107 | U9: 100.4 | V9: 106 | W9: 105.7 | X9: 105.2 | Y9: 105.5 | Z9: 103.5 | AA9: 103.8 | AB9: 104.2 | AC9: 104.9 | AD9: 105 | AE9: =DATE(B9, MATCH(C9,{"January","February","March","April","May","June","July","August","September","October","November","December"}, 0),1) -> 41334
A10: Rural+Urban | B10: 2013 | C10: March | D10: 111.4 | E10: 109.7 | F10: 111.2 | G10: 105.1 | H10: 104.9 | I10: 105.3 | J10: 102.2 | K10: 105 | L10: 104.2 | M10: 103 | N10: 106.2 | O10: 108.9 | P10: 106.9 | Q10: 106.6 | R10: 107.4 | S10: 106.5 | T10: 107.3 | U10: 100.4 | V10: 106.1 | W10: 105.6 | X10: 104.9 | Y10: 105.1 | Z10: 103.7 | AA10: 104 | AB10: 104.3 | AC10: 104.7 | AD10: 105.5 | AE10: =DATE(B10, MATCH(C10,{"January","February","March","April","May","June","July","August","September","October","November","December"}, 0),1) -> 41334
A11: Rural | B11: 2013 | C11: April | D11: 110.2 | E11: 109.5 | F11: 106.9 | G11: 106.3 | H11: 105.7 | I11: 108.3 | J11: 103.4 | K11: 105.7 | L11: 104.2 | M11: 103.2 | N11: 106.5 | O11: 108.8 | P11: 107.1 | Q11: 107.1 | R11: 108.1 | S11: 107.4 | T11: 108 | U11: =U12 -> 100.5 | V11: 106.5 | W11: 106.1 | X11: 105.1 | Y11: 104.4 | Z11: 104.5 | AA11: 104.8 | AB11: 102.7 | AC11: 104.6 | AD11: 106.4 | AE11: =DATE(B11, MATCH(C11,{"January","February","March","April","May","June","July","August","September","October","November","December"}, 0),1) -> 41365
A12: Urban | B12: 2013 | C12: April | D12: 114.6 | E12: 113.4 | F12: 106 | G12: 104.7 | H12: 102.1 | I12: 109.5 | J12: 109.7 | K12: 104.6 | L12: 102 | M12: 103.5 | N12: 108.2 | O12: 110.6 | P12: 108.8 | Q12: 108.5 | R12: 107.9 | S12: 106.4 | T12: 107.7 | U12: 100.5 | V12: 106.4 | W12: 106.5 | X12: 105.7 | Y12: 105 | Z12: 104 | AA12: 105.2 | AB12: 103.2 | AC12: 105.1 | AD12: 105.7 | AE12: =DATE(B12, MATCH(C12,{"January","February","March","April","May","June","July","August","September","October","November","December"}, 0),1) -> 41365
A13: Rural+Urban | B13: 2013 | C13: April | D13: 111.6 | E13: 110.9 | F13: 106.6 | G13: 105.7 | H13: 104.4 | I13: 108.9 | J13: 105.5 | K13: 105.3 | L13: 103.5 | M13: 103.3 | N13: 107.2 | O13: 109.6 | P13: 107.7 | Q13: 107.5 | R13: 108 | S13: 107 | T13: 107.9 | U13: 100.5 | V13: 106.5 | W13: 106.3 | X13: 105.3 | Y13: 104.7 | Z13: 104.2 | AA13: 105 | AB13: 102.9 | AC13: 104.8 | AD13: 106.1 | AE13: =DATE(B13, MATCH(C13,{"January","February","March","April","May","June","July","August","September","October","November","December"}, 0),1) -> 41365
A14: Rural | B14: 2013 | C14: May | D14: 110.9 | E14: 109.8 | F14: 105.9 | G14: 107.5 | H14: 105.3 | I14: 108.1 | J14: 107.3 | K14: 106.1 | L14: 103.7 | M14: 104 | N14: 107.4 | O14: 109.9 | P14: 108.1 | Q14: 108.1 | R14: 108.8 | S14: 107.9 | T14: 108.6 | U14: =U15 -> 100.5 | V14: 107.5 | W14: 106.8 | X14: 105.7 | Y14: 104.1 | Z14: 105 | AA14: 105.5 | AB14: 102.1 | AC14: 104.8 | AD14: 107.2 | AE14: =DATE(B14, MATCH(C14,{"January","February","March","April","May","June","July","August","September","October","November","December"}, 0),1) -> 41395
A15: Urban | B15: 2013 | C15: May | D15: 115.4 | E15: 114.2 | F15: 102.7 | G15: 105.5 | H15: 101.5 | I15: 110.6 | J15: 123.7 | K15: 105.2 | L15: 101.9 | M15: 105 | N15: 109.1 | O15: 111.3 | P15: 111.1 | Q15: 109.8 | R15: 108.5 | S15: 106.7 | T15: 108.3 | U15: 100.5 | V15: 107.2 | W15: 107.1 | X15: 106.2 | Y15: 103.9 | Z15: 104.6 | AA15: 105.7 | AB15: 102.6 | AC15: 104.9 | AD15: 106.6 | AE15: =DATE(B15, MATCH(C15,{"January","February","March","April","May","June","July","August","September","October","November","December"}, 0),1) -> 41395
A16: Rural+Urban | B16: 2013 | C16: May | D16: 112.3 | E16: 111.3 | F16: 104.7 | G16: 106.8 | H16: 103.9 | I16: 109.3 | J16: 112.9 | K16: 105.8 | L16: 103.1 | M16: 104.3 | N16: 108.1 | O16: 110.5 | P16: 109.2 | Q16: 108.6 | R16: 108.7 | S16: 107.4 | T16: 108.5 | U16: 100.5 | V16: 107.4 | W16: 106.9 | X16: 105.9 | Y16: 104 | Z16: 104.8 | AA16: 105.6 | AB16: 102.3 | AC16: 104.8 | AD16: 106.9 | AE16: =DATE(B16, MATCH(C16,{"January","February","March","April","May","June","July","August","September","October","November","December"}, 0),1) -> 41395
A17: Rural | B17: 2013 | C17: June | D17: 112.3 | E17: 112.1 | F17: 108.1 | G17: 108.3 | H17: 105.9 | I17: 109.2 | J17: 118 | K17: 106.8 | L17: 104.1 | M17: 105.4 | N17: 108.2 | O17: 111 | P17: 110.6 | Q17: 109 | R17: 109.7 | S17: 108.8 | T17: 109.5 | U17: =U18 -> 106.6 | V17: 108.5 | W17: 107.5 | X17: 106.3 | Y17: 105 | Z17: 105.6 | AA17: 106.5 | AB17: 102.5 | AC17: 105.5 | AD17: 108.9 | AE17: =DATE(B17, MATCH(C17,{"January","February","March","April","May","June","July","August","September","October","November","December"}, 0),1) -> 41426
A18: Urban | B18: 2013 | C18: June | D18: 117 | E18: 120.1 | F18: 112.5 | G18: 107.3 | H18: 101.3 | I18: 112.4 | J18: 143.6 | K18: 105.4 | L18: 101.4 | M18: 106.4 | N18: 110 | O18: 112.2 | P18: 115 | Q18: 110.9 | R18: 109.2 | S18: 107.2 | T18: 108.9 | U18: 106.6 | V18: 108 | W18: 107.7 | X18: 106.5 | Y18: 105.2 | Z18: 105.2 | AA18: 108.1 | AB18: 103.3 | AC18: 106.1 | AD18: 109.7 | AE18: =DATE(B18, MATCH(C18,{"January","February","March","April","May","June","July","August","September","October","November","December"}, 0),1) -> 41426
A19: Rural+Urban | B19: 2013 | C19: June | D19: 113.8 | E19: 114.9 | F19: 109.8 | G19: 107.9 | H19: 104.2 | I19: 110.7 | J19: 126.7 | K19: 106.3 | L19: 103.2 | M19: 105.7 | N19: 109 | O19: 111.6 | P19: 112.2 | Q19: 109.5 | R19: 109.5 | S19: 108.1 | T19: 109.3 | U19: 106.6 | V19: 108.3 | W19: 107.6 | X19: 106.4 | Y19: 105.1 | Z19: 105.4 | AA19: 107.4 | AB19: 102.8 | AC19: 105.8 | AD19: 109.3 | AE19: =DATE(B19, MATCH(C19,{"January","February","March","April","May","June","July","August","September","October","November","December"}, 0),1) -> 41426
A20: Rural | B20: 2013 | C20: July | D20: 113.4 | E20: 114.9 | F20: 110.5 | G20: 109.3 | H20: 106.2 | I20: 110.3 | J20: 129.2 | K20: 107.1 | L20: 104.3 | M20: 106.4 | N20: 109.1 | O20: 112.1 | P20: 113.1 | Q20: 109.8 | R20: 110.5 | S20: 109.5 | T20: 110.3 | U20: =U21 -> 107.7 | V20: 109.5 | W20: 108.3 | X20: 106.9 | Y20: 106.8 | Z20: 106.4 | AA20: 107.8 | AB20: 102.5 | AC20: 106.5 | AD20: 110.7 | AE20: =DATE(B20, MATCH(C20,{"January","February","March","April","May","June","July","August","September","October","November","December"}, 0),1) -> 41456
A21: Urban | B21: 2013 | C21: July | D21: 117.8 | E21: 119.2 | F21: 114 | G21: 108.3 | H21: 101.1 | I21: 113.2 | J21: 160.9 | K21: 105.1 | L21: 101.3 | M21: 107.5 | N21: 110.4 | O21: 113.1 | P21: 117.5 | Q21: 111.7 | R21: 109.8 | S21: 107.8 | T21: 109.5 | U21: 107.7 | V21: 108.6 | W21: 108.1 | X21: 107.1 | Y21: 107.3 | Z21: 105.9 | AA21: 110.1 | AB21: 103.2 | AC21: 107.3 | AD21: 111.4 | AE21: =DATE(B21, MATCH(C21,{"January","February","March","April","May","June","July","August","September","October","November","December"}, 0),1) -> 41456
A22: Rural+Urban | B22: 2013 | C22: July | D22: 114.8 | E22: 116.4 | F22: 111.9 | G22: 108.9 | H22: 104.3 | I22: 111.7 | J22: 140 | K22: 106.4 | L22: 103.3 | M22: 106.8 | N22: 109.6 | O22: 112.6 | P22: 114.7 | Q22: 110.3 | R22: 110.2 | S22: 108.8 | T22: 110 | U22: 107.7 | V22: 109.2 | W22: 108.2 | X22: 107 | Y22: 107.1 | Z22: 106.1 | AA22: 109.1 | AB22: 102.8 | AC22: 106.9 | AD22: 111 | AE22: =DATE(B22, MATCH(C22,{"January","February","March","April","May","June","July","August","September","October","November","December"}, 0),1) -> 41456
A23: Rural | B23: 2013 | C23: August | D23: 114.3 | E23: 115.4 | F23: 111.1 | G23: 110 | H23: 106.4 | I23: 110.8 | J23: 138.9 | K23: 107.4 | L23: 104.1 | M23: 106.9 | N23: 109.7 | O23: 112.6 | P23: 114.9 | Q23: 110.7 | R23: 111.3 | S23: 110.2 | T23: 111.1 | U23: =U24 -> 108.9 | V23: 109.9 | W23: 108.7 | X23: 107.5 | Y23: 107.8 | Z23: 106.8 | AA23: 108.7 | AB23: 105 | AC23: 107.5 | AD23: 112.1 | AE23: =DATE(B23, MATCH(C23,{"January","February","March","April","May","June","July","August","September","October","November","December"}, 0),1) -> 41487
A24: Urban | B24: 2013 | C24: August | D24: 118.3 | E24: 120.4 | F24: 112.7 | G24: 108.9 | H24: 101.1 | I24: 108.7 | J24: 177 | K24: 104.7 | L24: 101 | M24: 108.5 | N24: 110.9 | O24: 114.3 | P24: 119.6 | Q24: 112.4 | R24: 110.6 | S24: 108.3 | T24: 110.2 | U24: 108.9 | V24: 109.3 | W24: 108.7 | X24: 107.6 | Y24: 108.1 | Z24: 106.5 | AA24: 110.8 | AB24: 106 | AC24: 108.3 | AD24: 112.7 | AE24: =DATE(B24, MATCH(C24,{"January","February","March","April","May","June","July","August","September","October","November","December"}, 0),1) -> 41487
A25: Rural+Urban | B25: 2013 | C25: August | D25: 115.6 | E25: 117.2 | F25: 111.7 | G25: 109.6 | H25: 104.5 | I25: 109.8 | J25: 151.8 | K25: 106.5 | L25: 103.1 | M25: 107.4 | N25: 110.2 | O25: 113.4 | P25: 116.6 | Q25: 111.2 | R25: 111 | S25: 109.4 | T25: 110.7 | U25: 108.9 | V25: 109.7 | W25: 108.7 | X25: 107.5 | Y25: 108 | Z25: 106.6 | AA25: 109.9 | AB25: 105.4 | AC25: 107.9 | AD25: 112.4 | AE25: =DATE(B25, MATCH(C25,{"January","February","March","April","May","June","July","August","September","October","November","December"}, 0),1) -> 41487
A26: Rural | B26: 2013 | C26: September | D26: 115.4 | E26: 115.7 | F26: 111.7 | G26: 111 | H26: 107.4 | I26: 110.9 | J26: 154 | K26: 108.1 | L26: 104.2 | M26: 107.9 | N26: 110.4 | O26: 114 | P26: 117.8 | Q26: 111.7 | R26: 112.7 | S26: 111.4 | T26: 112.5 | U26: =U27 -> 109.7 | V26: 111.1 | W26: 109.6 | X26: 108.3 | Y26: 109.3 | Z26: 107.7 | AA26: 109.8 | AB26: 106.7 | AC26: 108.7 | AD26: 114.2 | AE26: =DATE(B26, MATCH(C26,{"January","February","March","April","May","June","July","August","September","October","November","December"}, 0),1) -> 41518
A27: Urban | B27: 2013 | C27: September | D27: 118.6 | E27: 119.1 | F27: 113.2 | G27: 109.6 | H27: 101.7 | I27: 103.2 | J27: 174.3 | K27: 105.1 | L27: 100.8 | M27: 109.1 | N27: 111.1 | O27: 115.4 | P27: 119.2 | Q27: 112.9 | R27: 111.4 | S27: 109 | T27: 111.1 | U27: 109.7 | V27: 109.5 | W27: 109.6 | X27: 107.9 | Y27: 110.4 | Z27: 107.4 | AA27: 111.2 | AB27: 106.9 | AC27: 109.4 | AD27: 113.2 | AE27: =DATE(B27, MATCH(C27,{"January","February","March","April","May","June","July","August","September","October","November","December"}, 0),1) -> 41518
A28: Rural+Urban | B28: 2013 | C28: September | D28: 116.4 | E28: 116.9 | F28: 112.3 | G28: 110.5 | H28: 105.3 | I28: 107.3 | J28: 160.9 | K28: 107.1 | L28: 103.1 | M28: 108.3 | N28: 110.7 | O28: 114.6 | P28: 118.3 | Q28: 112 | R28: 112.2 | S28: 110.4 | T28: 111.9 | U28: 109.7 | V28: 110.5 | W28: 109.6 | X28: 108.1 | Y28: 109.9 | Z28: 107.5 | AA28: 110.6 | AB28: 106.8 | AC28: 109 | AD28: 113.7 | AE28: =DATE(B28, MATCH(C28,{"January","February","March","April","May","June","July","August","September","October","November","December"}, 0),1) -> 41518
A29: Rural | B29: 2013 | C29: October | D29: 116.3 | E29: 115.4 | F29: 112.6 | G29: 111.7 | H29: 107.7 | I29: 113.2 | J29: 164.9 | K29: 108.3 | L29: 103.9 | M29: 108.2 | N29: 111.1 | O29: 114.9 | P29: 119.8 | Q29: 112.2 | R29: 113.6 | S29: 112.3 | T29: 113.4 | U29: =U30 -> 110.5 | V29: 111.6 | W29: 110.4 | X29: 108.9 | Y29: 109.3 | Z29: 108.3 | AA29: 110.2 | AB29: 107.5 | AC29: 109.1 | AD29: 115.5 | AE29: =DATE(B29, MATCH(C29,{"January","February","March","April","May","June","July","August","September","October","November","December"}, 0),1) -> 41548
A30: Urban | B30: 2013 | C30: October | D30: 118.9 | E30: 118.1 | F30: 114.5 | G30: 110.4 | H30: 102.3 | I30: 106.2 | J30: 183.5 | K30: 105.3 | L30: 100.2 | M30: 109.6 | N30: 111.4 | O30: 116 | P30: 120.8 | Q30: 113.5 | R30: 112.5 | S30: 109.7 | T30: 112 | U30: 110.5 | V30: 109.7 | W30: 110.2 | X30: 108.2 | Y30: 109.7 | Z30: 108 | AA30: 111.3 | AB30: 107.3 | AC30: 109.4 | AD30: 114 | AE30: =DATE(B30, MATCH(C30,{"January","February","March","April","May","June","July","August","September","October","November","December"}, 0),1) -> 41548
A31: Rural+Urban | B31: 2013 | C31: October | D31: 117.1 | E31: 116.3 | F31: 113.3 | G31: 111.2 | H31: 105.7 | I31: 109.9 | J31: 171.2 | K31: 107.3 | L31: 102.7 | M31: 108.7 | N31: 111.2 | O31: 115.4 | P31: 120.2 | Q31: 112.5 | R31: 113.2 | S31: 111.2 | T31: 112.8 | U31: 110.5 | V31: 110.9 | W31: 110.3 | X31: 108.6 | Y31: 109.5 | Z31: 108.1 | AA31: 110.8 | AB31: 107.4 | AC31: 109.2 | AD31: 114.8 | AE31: =DATE(B31, MATCH(C31,{"January","February","March","April","May","June","July","August","September","October","November","December"}, 0),1) -> 41548
A32: Rural | B32: 2013 | C32: November | D32: 117.3 | E32: 114.9 | F32: 116.2 | G32: 112.8 | H32: 108.9 | I32: 116.6 | J32: 178.1 | K32: 109.1 | L32: 103.6 | M32: 109 | N32: 111.8 | O32: 116 | P32: 122.5 | Q32: 112.8 | R32: 114.6 | S32: 113.1 | T32: 114.4 | U32: =U33 -> 111.1 | V32: 112.6 | W32: 111.3 | X32: 109.7 | Y32: 109.6 | Z32: 108.7 | AA32: 111 | AB32: 108.2 | AC32: 109.8 | AD32: 117.4 | AE32: =DATE(B32, MATCH(C32,{"January","February","March","April","May","June","July","August","September","October","November","December"}, 0),1) -> #N/A
A33: Urban | B33: 2013 | C33: November | D33: 119.8 | E33: 116.3 | F33: 122.6 | G33: 112 | H33: 103.2 | I33: 110 | J33: 192.8 | K33: 106.3 | L33: 99.5 | M33: 110.3 | N33: 111.8 | O33: 117.1 | P33: 122.9 | Q33: 114.1 | R33: 113.5 | S33: 110.3 | T33: 113 | U33: 111.1 | V33: 110 | W33: 110.9 | X33: 108.6 | Y33: 109.5 | Z33: 108.5 | AA33: 111.3 | AB33: 107.9 | AC33: 109.6 | AD33: 115 | AE33: =DATE(B33, MATCH(C33,{"January","February","March","April","May","June","July","August","September","October","November","December"}, 0),1) -> 41579
A34: Rural+Urban | B34: 2013 | C34: November | D34: 118.1 | E34: 115.4 | F34: 118.7 | G34: 112.5 | H34: 106.8 | I34: 113.5 | J34: 183.1 | K34: 108.2 | L34: 102.2 | M34: 109.4 | N34: 111.8 | O34: 116.5 | P34: 122.6 | Q34: 113.1 | R34: 114.2 | S34: 111.9 | T34: 113.8 | U34: 111.1 | V34: 111.6 | W34: 111.1 | X34: 109.3 | Y34: 109.5 | Z34: 108.6 | AA34: 111.2 | AB34: 108.1 | AC34: 109.7 | AD34: 116.3 | AE34: =DATE(B34, MATCH(C34,{"January","February","March","April","May","June","July","August","September","October","November","December"}, 0),1) -> 41579
A35: Rural | B35: 2013 | C35: December | D35: 118.4 | E35: 115.9 | F35: 120.4 | G35: 113.8 | H35: 109.5 | I35: 115.5 | J35: 145.7 | K35: 109.5 | L35: 102.9 | M35: 109.8 | N35: 112.1 | O35: 116.8 | P35: 118.7 | Q35: 113.6 | R35: 115.8 | S35: 114 | T35: 115.5 | U35: =U36 -> 110.7 | V35: 112.8 | W35: 112.1 | X35: 110.1 | Y35: 109.9 | Z35: 109.2 | AA35: 111.6 | AB35: 108.1 | AC35: 110.1 | AD35: 115.5 | AE35: =DATE(B35, MATCH(C35,{"January","February","March","April","May","June","July","August","September","October","November","December"}, 0),1) -> 41609
A36: Urban | B36: 2013 | C36: December | D36: 120.5 | E36: 118.1 | F36: 128.5 | G36: 112.8 | H36: 103.4 | I36: 110.7 | J36: 144.8 | K36: 107.1 | L36: 98.6 | M36: 111.9 | N36: 112.1 | O36: 118.1 | P36: 117.8 | Q36: 115 | R36: 114.2 | S36: 110.9 | T36: 113.7 | U36: 110.7 | V36: 110.4 | W36: 111.3 | X36: 109 | Y36: 109.7 | Z36: 108.9 | AA36: 111.4 | AB36: 107.7 | AC36: 109.8 | AD36: 113.3 | AE36: =DATE(B36, MATCH(C36,{"January","February","March","April","May","June","July","August","September","October","November","December"}, 0),1) -> 41609
A37: Rural+Urban | B37: 2013 | C37: December | D37: 119.1 | E37: 116.7 | F37: 123.5 | G37: 113.4 | H37: 107.3 | I37: 113.3 | J37: 145.4 | K37: 108.7 | L37: 101.5 | M37: 110.5 | N37: 112.1 | O37: 117.4 | P37: 118.4 | Q37: 114 | R37: 115.2 | S37: 112.7 | T37: 114.8 | U37: 110.7 | V37: 111.9 | W37: 111.7 | X37: 109.7 | Y37: 109.8 | Z37: 109 | AA37: 111.5 | AB37: 107.9 | AC37: 110 | AD37: 114.5 | AE37: =DATE(B37, MATCH(C37,{"January","February","March","April","May","June","July","August","September","October","November","December"}, 0),1) -> 41609
A38: Rural | B38: 2014 | C38: January | D38: 118.9 | E38: 117.1 | F38: 120.5 | G38: 114.4 | H38: 109 | I38: 115.5 | J38: 123.9 | K38: 109.6 | L38: 101.8 | M38: 110.2 | N38: 112.4 | O38: 117.3 | P38: 116 | Q38: 114 | R38: 116.5 | S38: 114.5 | T38: 116.2 | U38: =U39 -> 111.6 | V38: 113 | W38: 112.6 | X38: 110.6 | Y38: 110.5 | Z38: 109.6 | AA38: 111.8 | AB38: 108.3 | AC38: 110.6 | AD38: 114.2 | AE38: =DATE(B38, MATCH(C38,{"January","February","March","April","May","June","July","August","September","October","November","December"}, 0),1) -> 41640
A39: Urban | B39: 2014 | C39: January | D39: 121.2 | E39: 122 | F39: 129.9 | G39: 113.6 | H39: 102.9 | I39: 112.1 | J39: 118.9 | K39: 107.5 | L39: 96.9 | M39: 112.7 | N39: 112.1 | O39: 119 | P39: 115.5 | Q39: 115.7 | R39: 114.8 | S39: 111.3 | T39: 114.3 | U39: 111.6 | V39: 111 | W39: 111.9 | X39: 109.7 | Y39: 110.8 | Z39: 109.8 | AA39: 111.5 | AB39: 108 | AC39: 110.5 | AD39: 112.9 | AE39: =DATE(B39, MATCH(C39,{"January","February","March","April","May","June","July","August","September","October","November","December"}, 0),1) -> 41640
A40: Rural+Urban | B40: 2014 | C40: January | D40: 119.6 | E40: 118.8 | F40: 124.1 | G40: 114.1 | H40: 106.8 | I40: 113.9 | J40: 122.2 | K40: 108.9 | L40: 100.2 | M40: 111 | N40: 112.3 | O40: 118.1 | P40: 115.8 | Q40: 114.5 | R40: 115.8 | S40: 113.2 | T40: 115.4 | U40: 111.6 | V40: 112.2 | W40: 112.3 | X40: 110.3 | Y40: 110.7 | Z40: 109.7 | AA40: 111.6 | AB40: 108.2 | AC40: 110.6 | AD40: 113.6 | AE40: =DATE(B40, MATCH(C40,{"January","February","March","April","May","June","July","August","September","October","November","December"}, 0),1) -> 41640
...

Sheet Sheet1
A1: Sector | B1: Rural | C1: Urban | D1: Rural+Urban | E1: Rural | F1: Urban | G1: Rural+Urban | H1: Rural | I1: Urban | J1: Rural+Urban | K1: Rural | L1: Urban | M1: Rural+Urban | N1: Rural | O1: Urban | P1: Rural+Urban | Q1: Rural | R1: Urban | S1: Rural+Urban | T1: Rural | U1: Urban | V1: Rural+Urban | W1: Rural | X1: Urban | Y1: Rural+Urban | Z1: Rural | AA1: Urban | AB1: Rural+Urban | AC1: Rural | AD1: Urban | AE1: Rural+Urban | AF1: Rural | AG1: Urban | AH1: Rural+Urban | AI1: Rural | AJ1: Urban | AK1: Rural+Urban | AL1: Rural | AM1: Urban | AN1: Rural+Urban | AO1: Rural | AP1: Urban | AQ1: Rural+Urban | AR1: Rural | AS1: Urban | AT1: Rural+Urban | AU1: Rural | AV1: Urban | AW1: Rural+Urban | AX1: Rural | AY1: Urban | AZ1: Rural+Urban | BA1: Rural | BB1: Urban | BC1: Rural+Urban | BD1: Rural | BE1: Urban | BF1: Rural+Urban | BG1: Rural | BH1: Urban | BI1: Rural+Urban | BJ1: Rural | BK1: Urban | BL1: Rural+Urban | BM1: Rural | BN1: Urban | BO1: Rural+Urban | BP1: Rural | BQ1: Urban | BR1: Rural+Urban | BS1: Rural | BT1: Urban | BU1: Rural+Urban | BV1: Rural | BW1: Urban | BX1: Rural+Urban | BY1: Rural | BZ1: Urban | CA1: Rural+Urban | CB1: Rural | CC1: Urban | CD1: Rural+Urban | CE1: Rural | CF1: Urban | CG1: Rural+Urban | CH1: Rural | CI1: Urban | CJ1: Rural+Urban | CK1: Rural | CL1: Urban | CM1: Rural+Urban | CN1: Rural | CO1: Urban | CP1: Rural+Urban | CQ1: Rural | CR1: Urban | CS1: Rural+Urban | CT1: Rural | CU1: Urban | CV1: Rural+Urban | CW1: Rural | CX1: Urban | CY1: Rural+Urban | CZ1: Rural | DA1: Urban | DB1: Rural+Urban | DC1: Rural | DD1: Urban | DE1: Rural+Urban | DF1: Rural | DG1: Urban | DH1: Rural+Urban | DI1: Rural | DJ1: Urban | DK1: Rural+Urban | DL1: Rural | DM1: Urban | DN1: Rural+Urban | DO1: Rural | DP1: Urban | DQ1: Rural+Urban | DR1: Rural | DS1: Urban | DT1: Rural+Urban | DU1: Rural | DV1: Urban | DW1: Rural+Urban | DX1: Rural | DY1: Urban | DZ1: Rural+Urban | EA1: Rural | EB1: Urban | EC1: Rural+Urban | ED1: Rural | EE1: Urban | EF1: Rural+Urban | EG1: Rural | EH1: Urban | EI1: Rural+Urban | EJ1: Rural | EK1: Urban | EL1: Rural+Urban | EM1: Rural | EN1: Urban | EO1: Rural+Urban | EP1: Rural | EQ1: Urban | ER1: Rural+Urban | ES1: Rural | ET1: Urban | EU1: Rural+Urban | EV1: Rural | EW1: Urban | EX1: Rural+Urban | EY1: Rural | EZ1: Urban | FA1: Rural+Urban | FB1: Rural | FC1: Urban | FD1: Rural+Urban | FE1: Rural | FF1: Urban | FG1: Rural+Urban | FH1: Rural | FI1: Urban | FJ1: Rural+Urban | FK1: Rural | FL1: Urban | FM1: Rural+Urban | FN1: Rural | FO1: Urban | FP1: Rural+Urban | FQ1: Rural | FR1: Urban | FS1: Rural+Urban | FT1: Rural | FU1: Urban | FV1: Rural+Urban | FW1: Rural | FX1: Urban | FY1: Rural+Urban | FZ1: Rural | GA1: Urban | GB1: Rural+Urban | GC1: Rural | GD1: Urban | GE1: Rural+Urban | GF1: Rural | GG1: Urban | GH1: Rural+Urban | GI1: Rural | GJ1: Urban | GK1: Rural+Urban | GL1: Rural | GM1: Urban | GN1: Rural+Urban | GO1: Rural | GP1: Urban | GQ1: Rural+Urban | GR1: Rural | GS1: Urban | GT1: Rural+Urban | GU1: Rural | GV1: Urban | GW1: Rural+Urban | GX1: Rural | GY1: Urban | GZ1: Rural+Urban | HA1: Rural | HB1: Urban | HC1: Rural+Urban | HD1: Rural | HE1: Urban | HF1: Rural+Urban | HG1: Rural | HH1: Urban | HI1: Rural+Urban | HJ1: Rural | HK1: Urban | HL1: Rural+Urban | HM1: Rural | HN1: Urban | HO1: Rural+Urban | HP1: Rural | HQ1: Urban | HR1: Rural+Urban | HS1: Rural | HT1: Urban | HU1: Rural+Urban | HV1: Rural | HW1: Urban | HX1: Rural+Urban | HY1: Rural | HZ1: Urban | IA1: Rural+Urban | IB1: Rural | IC1: Urban | ID1: Rural+Urban | IE1: Rural | IF1: Urban | IG1: Rural+Urban | IH1: Rural | II1: Urban | IJ1: Rural+Urban | IK1: Rural | IL1: Urban | IM1: Rural+Urban | IN1: Rural | IO1: Urban | IP1: Rural+Urban | IQ1: Rural | IR1: Urban | IS1: Rural+Urban | IT1: Rural | IU1: Urban | IV1: Rural+Urban | IW1: Rural | IX1: Urban | IY1: Rural+Urban | IZ1: Rural | JA1: Urban | JB1: Rural+Urban | JC1: Rural | JD1: Urban | JE1: Rural+Urban | JF1: Rural | JG1: Urban | JH1: Rural+Urban | JI1: Rural | JJ1: Urban | JK1: Rural+Urban | JL1: Rural | JM1: Urban | JN1: Rural+Urban | JO1: Rural | JP1: Urban | JQ1: Rural+Urban | JR1: Rural | JS1: Urban | JT1: Rural+Urban | JU1: Rural | JV1: Urban | JW1: Rural+Urban | JX1: Rural | JY1: Urban | JZ1: Rural+Urban | KA1: Rural | KB1: Urban | KC1: Rural+Urban | KD1: Rural | KE1: Urban | KF1: Rural+Urban | KG1: Rural | KH1: Urban | KI1: Rural+Urban | KJ1: Rural | KK1: Urban | KL1: Rural+Urban | KM1: Rural | KN1: Urban | KO1: Rural+Urban | KP1: Rural | KQ1: Urban | KR1: Rural+Urban | KS1: Rural | KT1: Urban | KU1: Rural+Urban | KV1: Rural | KW1: Urban | KX1: Rural+Urban | KY1: Rural | KZ1: Urban | LA1: Rural+Urban | LB1: Rural | LC1: Urban | LD1: Rural+Urban | LE1: Rural | LF1: Urban | LG1: Rural+Urban | LH1: Rural | LI1: Urban | LJ1: Rural+Urban | LK1: Rural | LL1: Urban | LM1: Rural+Urban | LN1: Rural | LO1: Urban | LP1: Rural+Urban | LQ1: Rural | LR1: Urban | LS1: Rural+Urban | LT1: Rural | LU1: Urban | LV1: Rural+Urban | LW1: Rural | LX1: Urban | LY1: Rural+Urban | LZ1: Rural | MA1: Urban | MB1: Rural+Urban | MC1: Rural | MD1: Urban | ME1: Rural+Urban | MF1: Rural | MG1: Urban | MH1: Rural+Urban | MI1: Rural | MJ1: Urban | MK1: Rural+Urban | ML1: Rural | MM1: Urban | MN1: Rural+Urban | MO1: Rural | MP1: Urban | MQ1: Rural+Urban | MR1: Rural | MS1: Urban | MT1: Rural+Urban | MU1: Rural | MV1: Urban | MW1: Rural+Urban | MX1: Rural | MY1: Urban | MZ1: Rural+Urban | NA1: Rural | NB1: Urban | NC1: Rural+Urban | ND1: Rural | NE1: Urban | NF1: Rural+Urban | NG1: Rural | NH1: Urban | NI1: Rural+Urban
A2: Year | B2: 2013 | C2: 2013 | D2: 2013 | E2: 2013 | F2: 2013 | G2: 2013 | H2: 2013 | I2: 2013 | J2: 2013 | K2: 2013 | L2: 2013 | M2: 2013 | N2: 2013 | O2: 2013 | P2: 2013 | Q2: 2013 | R2: 2013 | S2: 2013 | T2: 2013 | U2: 2013 | V2: 2013 | W2: 2013 | X2: 2013 | Y2: 2013 | Z2: 2013 | AA2: 2013 | AB2: 2013 | AC2: 2013 | AD2: 2013 | AE2: 2013 | AF2: 2013 | AG2: 2013 | AH2: 2013 | AI2: 2013 | AJ2: 2013 | AK2: 2013 | AL2: 2014 | AM2: 2014 | AN2: 2014 | AO2: 2014 | AP2: 2014 | AQ2: 2014 | AR2: 2014 | AS2: 2014 | AT2: 2014 | AU2: 2014 | AV2: 2014 | AW2: 2014 | AX2: 2014 | AY2: 2014 | AZ2: 2014 | BA2: 2014 | BB2: 2014 | BC2: 2014 | BD2: 2014 | BE2: 2014 | BF2: 2014 | BG2: 2014 | BH2: 2014 | BI2: 2014 | BJ2: 2014 | BK2: 2014 | BL2: 2014 | BM2: 2014 | BN2: 2014 | BO2: 2014 | BP2: 2014 | BQ2: 2014 | BR2: 2014 | BS2: 2014 | BT2: 2014 | BU2: 2014 | BV2: 2015 | BW2: 2015 | BX2: 2015 | BY2: 2015 | BZ2: 2015 | CA2: 2015 | CB2: 2015 | CC2: 2015 | CD2: 2015 | CE2: 2015 | CF2: 2015 | CG2: 2015 | CH2: 2015 | CI2: 2015 | CJ2: 2015 | CK2: 2015 | CL2: 2015 | CM2: 2015 | CN2: 2015 | CO2: 2015 | CP2: 2015 | CQ2: 2015 | CR2: 2015 | CS2: 2015 | CT2: 2015 | CU2: 2015 | CV2: 2015 | CW2: 2015 | CX2: 2015 | CY2: 2015 | CZ2: 2015 | DA2: 2015 | DB2: 2015 | DC2: 2015 | DD2: 2015 | DE2: 2015 | DF2: 2016 | DG2: 2016 | DH2: 2016 | DI2: 2016 | DJ2: 2016 | DK2: 2016 | DL2: 2016 | DM2: 2016 | DN2: 2016 | DO2: 2016 | DP2: 2016 | DQ2: 2016 | DR2: 2016 | DS2: 2016 | DT2: 2016 | DU2: 2016 | DV2: 2016 | DW2: 2016 | DX2: 2016 | DY2: 2016 | DZ2: 2016 | EA2: 2016 | EB2: 2016 | EC2: 2016 | ED2: 2016 | EE2: 2016 | EF2: 2016 | EG2: 2016 | EH2: 2016 | EI2: 2016 | EJ2: 2016 | EK2: 2016 | EL2: 2016 | EM2: 2016 | EN2: 2016 | EO2: 2016 | EP2: 2017 | EQ2: 2017 | ER2: 2017 | ES2: 2017 | ET2: 2017 | EU2: 2017 | EV2: 2017 | EW2: 2017 | EX2: 2017 | EY2: 2017 | EZ2: 2017 | FA2: 2017 | FB2: 2017 | FC2: 2017 | FD2: 2017 | FE2: 2017 | FF2: 2017 | FG2: 2017 | FH2: 2017 | FI2: 2017 | FJ2: 2017 | FK2: 2017 | FL2: 2017 | FM2: 2017 | FN2: 2017 | FO2: 2017 | FP2: 2017 | FQ2: 2017 | FR2: 2017 | FS2: 2017 | FT2: 2017 | FU2: 2017 | FV2: 2017 | FW2: 2017 | FX2: 2017 | FY2: 2017 | FZ2: 2018 | GA2: 2018 | GB2: 2018 | GC2: 2018 | GD2: 2018 | GE2: 2018 | GF2: 2018 | GG2: 2018 | GH2: 2018 | GI2: 2018 | GJ2: 2018 | GK2: 2018 | GL2: 2018 | GM2: 2018 | GN2: 2018 | GO2: 2018 | GP2: 2018 | GQ2: 2018 | GR2: 2018 | GS2: 2018 | GT2: 2018 | GU2: 2018 | GV2: 2018 | GW2: 2018 | GX2: 2018 | GY2: 2018 | GZ2: 2018 | HA2: 2018 | HB2: 2018 | HC2: 2018 | HD2: 2018 | HE2: 2018 | HF2: 2018 | HG2: 2018 | HH2: 2018 | HI2: 2018 | HJ2: 2019 | HK2: 2019 | HL2: 2019 | HM2: 2019 | HN2: 2019 | HO2: 2019 | HP2: 2019 | HQ2: 2019 | HR2: 2019 | HS2: 2019 | HT2: 2019 | HU2: 2019 | HV2: 2019 | HW2: 2019 | HX2: 2019 | HY2: 2019 | HZ2: 2019 | IA2: 2019 | IB2: 2019 | IC2: 2019 | ID2: 2019 | IE2: 2019 | IF2: 2019 | IG2: 2019 | IH2: 2019 | II2: 2019 | IJ2: 2019 | IK2: 2019 | IL2: 2019 | IM2: 2019 | IN2: 2019 | IO2: 2019 | IP2: 2019 | IQ2: 2020 | IR2: 2020 | IS2: 2020 | IT2: 2020 | IU2: 2020 | IV2: 2020 | IW2: 2020 | IX2: 2020 | IY2: 2020 | IZ2: 2020 | JA2: 2020 | JB2: 2020 | JC2: 2020 | JD2: 2020 | JE2: 2020 | JF2: 2020 | JG2: 2020 | JH2: 2020 | JI2: 2020 | JJ2: 2020 | JK2: 2020 | JL2: 2020 | JM2: 2020 | JN2: 2020 | JO2: 2020 | JP2: 2020 | JQ2: 2020 | JR2: 2020 | JS2: 2020 | JT2: 2020 | JU2: 2020 | JV2: 2020 | JW2: 2020 | JX2: 2020 | JY2: 2020 | JZ2: 2020 | KA2: 2021 | KB2: 2021 | KC2: 2021 | KD2: 2021 | KE2: 2021 | KF2: 2021 | KG2: 2021 | KH2: 2021 | KI2: 2021 | KJ2: 2021 | KK2: 2021 | KL2: 2021 | KM2: 2021 | KN2: 2021 | KO2: 2021 | KP2: 2021 | KQ2: 2021 | KR2: 2021 | KS2: 2021 | KT2: 2021 | KU2: 2021 | KV2: 2021 | KW2: 2021 | KX2: 2021 | KY2: 2021 | KZ2: 2021 | LA2: 2021 | LB2: 2021 | LC2: 2021 | LD2: 2021 | LE2: 2021 | LF2: 2021 | LG2: 2021 | LH2: 2021 | LI2: 2021 | LJ2: 2021 | LK2: 2022 | LL2: 2022 | LM2: 2022 | LN2: 2022 | LO2: 2022 | LP2: 2022 | LQ2: 2022 | LR2: 2022 | LS2: 2022 | LT2: 2022 | LU2: 2022 | LV2: 2022 | LW2: 2022 | LX2: 2022 | LY2: 2022 | LZ2: 2022 | MA2: 2022 | MB2: 2022 | MC2: 2022 | MD2: 2022 | ME2: 2022 | MF2: 2022 | MG2: 2022 | MH2: 2022 | MI2: 2022 | MJ2: 2022 | MK2: 2022 | ML2: 2022 | MM2: 2022 | MN2: 2022 | MO2: 2022 | MP2: 2022 | MQ2: 2022 | MR2: 2022 | MS2: 2022 | MT2: 2022 | MU2: 2023 | MV2: 2023 | MW2: 2023 | MX2: 2023 | MY2: 2023 | MZ2: 2023 | NA2: 2023 | NB2: 2023 | NC2: 2023 | ND2: 2023 | NE2: 2023 | NF2: 2023 | NG2: 2023 | NH2: 2023 | NI2: 2023
